<?xml version='1.0' encoding='utf-8'?>
<robot name="quad2">
  <joint name="front_left_ankle" type="revolute">
    <origin xyz="0.000000 -10.000000 0.000000" rpy="0. 0. 0." />
    <parent link="front_left_lower_leg" />
    <child link="front_left_foot" />
    <axis xyz="0. 0. 1." />
    <limit lower="0." upper="3.1415927" effort="0." velocity="0." />
  </joint>
  <joint name="front_left_hip" type="revolute">
    <origin xyz="-31.015000 24.810300 -19.280000" rpy="0. 0. 0." />
    <parent link="Root" />
    <child link="front_left_upper_leg" />
    <axis xyz="0. 1. 0." />
    <limit lower="-1.5707963" upper="1.5707963" effort="0." velocity="0." />
  </joint>
  <joint name="front_left_knee" type="revolute">
    <origin xyz="-4.985001 0.689700 -0.090300" rpy="0. 0. 0." />
    <parent link="front_left_upper_leg" />
    <child link="front_left_lower_leg" />
    <axis xyz="0. 0. 1." />
    <limit lower="-3.1415927" upper="0." effort="0." velocity="0." />
  </joint>
  <joint name="front_right_ankle" type="revolute">
    <origin xyz="0.000000 -10.000000 0.000000" rpy="0. 0. 0." />
    <parent link="front_right_lower_leg" />
    <child link="front_right_foot" />
    <axis xyz="0. 0. 1." />
    <limit lower="-3.1415927" upper="0." effort="0." velocity="0." />
  </joint>
  <joint name="front_right_hip" type="revolute">
    <origin xyz="-7.485000 24.810300 -19.280000" rpy="0. 0. 0." />
    <parent link="Root" />
    <child link="front_right_upper_leg" />
    <axis xyz="0. 1. 0." />
    <limit lower="-1.5707963" upper="1.5707963" effort="0." velocity="0." />
  </joint>
  <joint name="front_right_knee" type="revolute">
    <origin xyz="4.985000 0.689700 -0.090300" rpy="0. 0. 0." />
    <parent link="front_right_upper_leg" />
    <child link="front_right_lower_leg" />
    <axis xyz="0. 0. 1." />
    <limit lower="0." upper="3.1415927" effort="0." velocity="0." />
  </joint>
  <joint name="rear_left_ankle" type="revolute">
    <origin xyz="0.000000 -10.000000 0.000000" rpy="0. 0. 0." />
    <parent link="rear_left_lower_leg" />
    <child link="rear_left_foot" />
    <axis xyz="0. 0. 1." />
    <limit lower="0." upper="3.1415927" effort="0." velocity="0." />
  </joint>
  <joint name="rear_left_hip" type="revolute">
    <origin xyz="-31.015000 24.810300 -4.280000" rpy="0. 0. 0." />
    <parent link="Root" />
    <child link="rear_left_upper_leg" />
    <axis xyz="0. 1. 0." />
    <limit lower="-1.5707963" upper="1.5707963" effort="0." velocity="0." />
  </joint>
  <joint name="rear_left_knee" type="revolute">
    <origin xyz="-4.985001 0.689700 0.090300" rpy="0. 0. 0." />
    <parent link="rear_left_upper_leg" />
    <child link="rear_left_lower_leg" />
    <axis xyz="0. 0. 1." />
    <limit lower="-3.1415927" upper="0." effort="0." velocity="0." />
  </joint>
  <joint name="rear_right_ankle" type="revolute">
    <origin xyz="0.000000 -10.000000 0.000000" rpy="0. 0. 0." />
    <parent link="rear_right_lower_leg" />
    <child link="rear_right_foot" />
    <axis xyz="0. 0. 1." />
    <limit lower="-3.1415927" upper="0." effort="0." velocity="0." />
  </joint>
  <joint name="rear_right_hip" type="revolute">
    <origin xyz="-7.485000 24.810300 -4.280000" rpy="0. 0. 0." />
    <parent link="Root" />
    <child link="rear_right_upper_leg" />
    <axis xyz="0. 1. 0." />
    <limit lower="-1.5707963" upper="1.5707963" effort="0." velocity="0." />
  </joint>
  <joint name="rear_right_knee" type="revolute">
    <origin xyz="4.985000 0.689700 0.090300" rpy="0. 0. 0." />
    <parent link="rear_right_upper_leg" />
    <child link="rear_right_lower_leg" />
    <axis xyz="0. 0. 1." />
    <limit lower="0." upper="3.1415927" effort="0." velocity="0." />
  </joint>
  <link name="Root">
    <visual>
      <origin xyz="0.000000 0.000000 0.000000" rpy="0. 0. 0." />
      <geometry>
        <mesh filename="meshes/mesh0.obj" scale="0.100000 0.100000 0.100000" />
      </geometry>
    </visual>
    <visual>
      <origin xyz="0.000000 0.000000 0.000000" rpy="0. 0. 0." />
      <geometry>
        <mesh filename="meshes/mesh1.obj" scale="0.100000 0.100000 0.100000" />
      </geometry>
    </visual>
    <visual>
      <origin xyz="0.000000 0.000000 0.000000" rpy="0. 0. 0." />
      <geometry>
        <mesh filename="meshes/mesh2.obj" scale="0.100000 0.100000 0.100000" />
      </geometry>
    </visual>
    <visual>
      <origin xyz="0.000000 0.000000 0.000000" rpy="0. 0. 0." />
      <geometry>
        <mesh filename="meshes/mesh3.obj" scale="0.100000 0.100000 0.100000" />
      </geometry>
    </visual>
    <visual>
      <origin xyz="0.000000 0.000000 0.000000" rpy="0. 0. 0." />
      <geometry>
        <mesh filename="meshes/mesh4.obj" scale="0.100000 0.100000 0.100000" />
      </geometry>
    </visual>
    <visual>
      <origin xyz="0.000000 0.000000 0.000000" rpy="0. 0. 0." />
      <geometry>
        <mesh filename="meshes/mesh5.obj" scale="0.100000 0.100000 0.100000" />
      </geometry>
    </visual>
    <visual>
      <origin xyz="0.000000 0.000000 0.000000" rpy="0. 0. 0." />
      <geometry>
        <mesh filename="meshes/mesh6.obj" scale="0.100000 0.100000 0.100000" />
      </geometry>
    </visual>
    <visual>
      <origin xyz="0.000000 0.000000 0.000000" rpy="0. 0. 0." />
      <geometry>
        <mesh filename="meshes/mesh7.obj" scale="0.100000 0.100000 0.100000" />
      </geometry>
    </visual>
    <visual>
      <origin xyz="0.000000 0.000000 0.000000" rpy="0. 0. 0." />
      <geometry>
        <mesh filename="meshes/mesh8.obj" scale="0.100000 0.100000 0.100000" />
      </geometry>
    </visual>
    <visual>
      <origin xyz="0.000000 0.000000 0.000000" rpy="0. 0. 0." />
      <geometry>
        <mesh filename="meshes/mesh9.obj" scale="0.100000 0.100000 0.100000" />
      </geometry>
    </visual>
    <visual>
      <origin xyz="0.000000 0.000000 0.000000" rpy="0. 0. 0." />
      <geometry>
        <mesh filename="meshes/mesh10.obj" scale="0.100000 0.100000 0.100000" />
      </geometry>
    </visual>
    <visual>
      <origin xyz="0.000000 0.000000 0.000000" rpy="0. 0. 0." />
      <geometry>
        <mesh filename="meshes/mesh11.obj" scale="0.100000 0.100000 0.100000" />
      </geometry>
    </visual>
    <visual>
      <origin xyz="0.000000 0.000000 0.000000" rpy="0. 0. 0." />
      <geometry>
        <mesh filename="meshes/mesh12.obj" scale="0.100000 0.100000 0.100000" />
      </geometry>
    </visual>
    <visual>
      <origin xyz="0.000000 0.000000 0.000000" rpy="0. 0. 0." />
      <geometry>
        <mesh filename="meshes/mesh13.obj" scale="0.100000 0.100000 0.100000" />
      </geometry>
    </visual>
    <visual>
      <origin xyz="0.000000 0.000000 0.000000" rpy="0. 0. 0." />
      <geometry>
        <mesh filename="meshes/mesh14.obj" scale="0.100000 0.100000 0.100000" />
      </geometry>
    </visual>
    <visual>
      <origin xyz="0.000000 0.000000 0.000000" rpy="0. 0. 0." />
      <geometry>
        <mesh filename="meshes/mesh15.obj" scale="0.100000 0.100000 0.100000" />
      </geometry>
    </visual>
    <visual>
      <origin xyz="0.000000 0.000000 0.000000" rpy="0. 0. 0." />
      <geometry>
        <mesh filename="meshes/mesh16.obj" scale="0.100000 0.100000 0.100000" />
      </geometry>
    </visual>
    <visual>
      <origin xyz="0.000000 0.000000 0.000000" rpy="0. 0. 0." />
      <geometry>
        <mesh filename="meshes/mesh17.obj" scale="0.100000 0.100000 0.100000" />
      </geometry>
    </visual>
    <visual>
      <origin xyz="0.000000 0.000000 0.000000" rpy="0. 0. 0." />
      <geometry>
        <mesh filename="meshes/mesh18.obj" scale="0.100000 0.100000 0.100000" />
      </geometry>
    </visual>
    <visual>
      <origin xyz="0.000000 0.000000 0.000000" rpy="0. 0. 0." />
      <geometry>
        <mesh filename="meshes/mesh19.obj" scale="0.100000 0.100000 0.100000" />
      </geometry>
    </visual>
    <visual>
      <origin xyz="0.000000 0.000000 0.000000" rpy="0. 0. 0." />
      <geometry>
        <mesh filename="meshes/mesh20.obj" scale="0.100000 0.100000 0.100000" />
      </geometry>
    </visual>
    <visual>
      <origin xyz="0.000000 0.000000 0.000000" rpy="0. 0. 0." />
      <geometry>
        <mesh filename="meshes/mesh21.obj" scale="0.100000 0.100000 0.100000" />
      </geometry>
    </visual>
    <visual>
      <origin xyz="0.000000 0.000000 0.000000" rpy="0. 0. 0." />
      <geometry>
        <mesh filename="meshes/mesh22.obj" scale="0.100000 0.100000 0.100000" />
      </geometry>
    </visual>
    <visual>
      <origin xyz="0.000000 0.000000 0.000000" rpy="0. 0. 0." />
      <geometry>
        <mesh filename="meshes/mesh23.obj" scale="0.100000 0.100000 0.100000" />
      </geometry>
    </visual>
    <visual>
      <origin xyz="0.000000 0.000000 0.000000" rpy="0. 0. 0." />
      <geometry>
        <mesh filename="meshes/mesh24.obj" scale="0.100000 0.100000 0.100000" />
      </geometry>
    </visual>
    <visual>
      <origin xyz="0.000000 0.000000 0.000000" rpy="0. 0. 0." />
      <geometry>
        <mesh filename="meshes/mesh25.obj" scale="0.100000 0.100000 0.100000" />
      </geometry>
    </visual>
    <visual>
      <origin xyz="0.000000 0.000000 0.000000" rpy="0. 0. 0." />
      <geometry>
        <mesh filename="meshes/mesh26.obj" scale="0.100000 0.100000 0.100000" />
      </geometry>
    </visual>
    <visual>
      <origin xyz="0.000000 0.000000 0.000000" rpy="0. 0. 0." />
      <geometry>
        <mesh filename="meshes/mesh27.obj" scale="0.100000 0.100000 0.100000" />
      </geometry>
    </visual>
    <visual>
      <origin xyz="0.000000 0.000000 0.000000" rpy="0. 0. 0." />
      <geometry>
        <mesh filename="meshes/mesh28.obj" scale="0.100000 0.100000 0.100000" />
      </geometry>
    </visual>
    <visual>
      <origin xyz="0.000000 0.000000 0.000000" rpy="0. 0. 0." />
      <geometry>
        <mesh filename="meshes/mesh29.obj" scale="0.100000 0.100000 0.100000" />
      </geometry>
    </visual>
    <visual>
      <origin xyz="0.000000 0.000000 0.000000" rpy="0. 0. 0." />
      <geometry>
        <mesh filename="meshes/mesh30.obj" scale="0.100000 0.100000 0.100000" />
      </geometry>
    </visual>
    <visual>
      <origin xyz="0.000000 0.000000 0.000000" rpy="0. 0. 0." />
      <geometry>
        <mesh filename="meshes/mesh31.obj" scale="0.100000 0.100000 0.100000" />
      </geometry>
    </visual>
    <visual>
      <origin xyz="0.000000 0.000000 0.000000" rpy="0. 0. 0." />
      <geometry>
        <mesh filename="meshes/mesh32.obj" scale="0.100000 0.100000 0.100000" />
      </geometry>
    </visual>
    <visual>
      <origin xyz="0.000000 0.000000 0.000000" rpy="0. 0. 0." />
      <geometry>
        <mesh filename="meshes/mesh33.obj" scale="0.100000 0.100000 0.100000" />
      </geometry>
    </visual>
    <visual>
      <origin xyz="0.000000 0.000000 0.000000" rpy="0. 0. 0." />
      <geometry>
        <mesh filename="meshes/mesh34.obj" scale="0.100000 0.100000 0.100000" />
      </geometry>
    </visual>
    <visual>
      <origin xyz="0.000000 0.000000 0.000000" rpy="0. 0. 0." />
      <geometry>
        <mesh filename="meshes/mesh35.obj" scale="0.100000 0.100000 0.100000" />
      </geometry>
    </visual>
    <visual>
      <origin xyz="0.000000 0.000000 0.000000" rpy="0. 0. 0." />
      <geometry>
        <mesh filename="meshes/mesh36.obj" scale="0.100000 0.100000 0.100000" />
      </geometry>
    </visual>
    <visual>
      <origin xyz="0.000000 0.000000 0.000000" rpy="0. 0. 0." />
      <geometry>
        <mesh filename="meshes/mesh37.obj" scale="0.100000 0.100000 0.100000" />
      </geometry>
    </visual>
    <visual>
      <origin xyz="0.000000 0.000000 0.000000" rpy="0. 0. 0." />
      <geometry>
        <mesh filename="meshes/mesh38.obj" scale="0.100000 0.100000 0.100000" />
      </geometry>
    </visual>
    <visual>
      <origin xyz="0.000000 0.000000 0.000000" rpy="0. 0. 0." />
      <geometry>
        <mesh filename="meshes/mesh39.obj" scale="0.100000 0.100000 0.100000" />
      </geometry>
    </visual>
    <visual>
      <origin xyz="0.000000 0.000000 0.000000" rpy="0. 0. 0." />
      <geometry>
        <mesh filename="meshes/mesh40.obj" scale="0.100000 0.100000 0.100000" />
      </geometry>
    </visual>
    <visual>
      <origin xyz="0.000000 0.000000 0.000000" rpy="0. 0. 0." />
      <geometry>
        <mesh filename="meshes/mesh41.obj" scale="0.100000 0.100000 0.100000" />
      </geometry>
    </visual>
    <visual>
      <origin xyz="0.000000 0.000000 0.000000" rpy="0. 0. 0." />
      <geometry>
        <mesh filename="meshes/mesh42.obj" scale="0.100000 0.100000 0.100000" />
      </geometry>
    </visual>
    <visual>
      <origin xyz="0.000000 0.000000 0.000000" rpy="0. 0. 0." />
      <geometry>
        <mesh filename="meshes/mesh43.obj" scale="0.100000 0.100000 0.100000" />
      </geometry>
    </visual>
    <visual>
      <origin xyz="0.000000 0.000000 0.000000" rpy="0. 0. 0." />
      <geometry>
        <mesh filename="meshes/mesh44.obj" scale="0.100000 0.100000 0.100000" />
      </geometry>
    </visual>
    <visual>
      <origin xyz="0.000000 0.000000 0.000000" rpy="0. 0. 0." />
      <geometry>
        <mesh filename="meshes/mesh45.obj" scale="0.100000 0.100000 0.100000" />
      </geometry>
    </visual>
    <visual>
      <origin xyz="0.000000 0.000000 0.000000" rpy="0. 0. 0." />
      <geometry>
        <mesh filename="meshes/mesh46.obj" scale="0.100000 0.100000 0.100000" />
      </geometry>
    </visual>
    <visual>
      <origin xyz="0.000000 0.000000 0.000000" rpy="0. 0. 0." />
      <geometry>
        <mesh filename="meshes/mesh47.obj" scale="0.100000 0.100000 0.100000" />
      </geometry>
    </visual>
    <visual>
      <origin xyz="0.000000 0.000000 0.000000" rpy="0. 0. 0." />
      <geometry>
        <mesh filename="meshes/mesh48.obj" scale="0.100000 0.100000 0.100000" />
      </geometry>
    </visual>
    <visual>
      <origin xyz="0.000000 0.000000 0.000000" rpy="0. 0. 0." />
      <geometry>
        <mesh filename="meshes/mesh49.obj" scale="0.100000 0.100000 0.100000" />
      </geometry>
    </visual>
    <visual>
      <origin xyz="0.000000 0.000000 0.000000" rpy="0. 0. 0." />
      <geometry>
        <mesh filename="meshes/mesh50.obj" scale="0.100000 0.100000 0.100000" />
      </geometry>
    </visual>
    <visual>
      <origin xyz="0.000000 0.000000 0.000000" rpy="0. 0. 0." />
      <geometry>
        <mesh filename="meshes/mesh51.obj" scale="0.100000 0.100000 0.100000" />
      </geometry>
    </visual>
    <visual>
      <origin xyz="0.000000 0.000000 0.000000" rpy="0. 0. 0." />
      <geometry>
        <mesh filename="meshes/mesh52.obj" scale="0.100000 0.100000 0.100000" />
      </geometry>
    </visual>
    <visual>
      <origin xyz="0.000000 0.000000 0.000000" rpy="0. 0. 0." />
      <geometry>
        <mesh filename="meshes/mesh53.obj" scale="0.100000 0.100000 0.100000" />
      </geometry>
    </visual>
    <visual>
      <origin xyz="0.000000 0.000000 0.000000" rpy="0. 0. 0." />
      <geometry>
        <mesh filename="meshes/mesh54.obj" scale="0.100000 0.100000 0.100000" />
      </geometry>
    </visual>
    <visual>
      <origin xyz="0.000000 0.000000 0.000000" rpy="0. 0. 0." />
      <geometry>
        <mesh filename="meshes/mesh55.obj" scale="0.100000 0.100000 0.100000" />
      </geometry>
    </visual>
    <visual>
      <origin xyz="0.000000 0.000000 0.000000" rpy="0. 0. 0." />
      <geometry>
        <mesh filename="meshes/mesh56.obj" scale="0.100000 0.100000 0.100000" />
      </geometry>
    </visual>
    <visual>
      <origin xyz="0.000000 0.000000 0.000000" rpy="0. 0. 0." />
      <geometry>
        <mesh filename="meshes/mesh57.obj" scale="0.100000 0.100000 0.100000" />
      </geometry>
    </visual>
    <visual>
      <origin xyz="0.000000 0.000000 0.000000" rpy="0. 0. 0." />
      <geometry>
        <mesh filename="meshes/mesh58.obj" scale="0.100000 0.100000 0.100000" />
      </geometry>
    </visual>
    <visual>
      <origin xyz="0.000000 0.000000 0.000000" rpy="0. 0. 0." />
      <geometry>
        <mesh filename="meshes/mesh59.obj" scale="0.100000 0.100000 0.100000" />
      </geometry>
    </visual>
    <visual>
      <origin xyz="0.000000 0.000000 0.000000" rpy="0. 0. 0." />
      <geometry>
        <mesh filename="meshes/mesh60.obj" scale="0.100000 0.100000 0.100000" />
      </geometry>
    </visual>
    <visual>
      <origin xyz="0.000000 0.000000 0.000000" rpy="0. 0. 0." />
      <geometry>
        <mesh filename="meshes/mesh61.obj" scale="0.100000 0.100000 0.100000" />
      </geometry>
    </visual>
    <visual>
      <origin xyz="0.000000 0.000000 0.000000" rpy="0. 0. 0." />
      <geometry>
        <mesh filename="meshes/mesh62.obj" scale="0.100000 0.100000 0.100000" />
      </geometry>
    </visual>
    <visual>
      <origin xyz="0.000000 0.000000 0.000000" rpy="0. 0. 0." />
      <geometry>
        <mesh filename="meshes/mesh63.obj" scale="0.100000 0.100000 0.100000" />
      </geometry>
    </visual>
    <visual>
      <origin xyz="0.000000 0.000000 0.000000" rpy="0. 0. 0." />
      <geometry>
        <mesh filename="meshes/mesh64.obj" scale="0.100000 0.100000 0.100000" />
      </geometry>
    </visual>
    <visual>
      <origin xyz="0.000000 0.000000 0.000000" rpy="0. 0. 0." />
      <geometry>
        <mesh filename="meshes/mesh65.obj" scale="0.100000 0.100000 0.100000" />
      </geometry>
    </visual>
    <visual>
      <origin xyz="0.000000 0.000000 0.000000" rpy="0. 0. 0." />
      <geometry>
        <mesh filename="meshes/mesh66.obj" scale="0.100000 0.100000 0.100000" />
      </geometry>
    </visual>
    <visual>
      <origin xyz="0.000000 0.000000 0.000000" rpy="0. 0. 0." />
      <geometry>
        <mesh filename="meshes/mesh67.obj" scale="0.100000 0.100000 0.100000" />
      </geometry>
    </visual>
    <visual>
      <origin xyz="0.000000 0.000000 0.000000" rpy="0. 0. 0." />
      <geometry>
        <mesh filename="meshes/mesh68.obj" scale="0.100000 0.100000 0.100000" />
      </geometry>
    </visual>
    <visual>
      <origin xyz="0.000000 0.000000 0.000000" rpy="0. 0. 0." />
      <geometry>
        <mesh filename="meshes/mesh69.obj" scale="0.100000 0.100000 0.100000" />
      </geometry>
    </visual>
    <visual>
      <origin xyz="0.000000 0.000000 0.000000" rpy="0. 0. 0." />
      <geometry>
        <mesh filename="meshes/mesh70.obj" scale="0.100000 0.100000 0.100000" />
      </geometry>
    </visual>
    <visual>
      <origin xyz="0.000000 0.000000 0.000000" rpy="0. 0. 0." />
      <geometry>
        <mesh filename="meshes/mesh71.obj" scale="0.100000 0.100000 0.100000" />
      </geometry>
    </visual>
    <visual>
      <origin xyz="0.000000 0.000000 0.000000" rpy="0. 0. 0." />
      <geometry>
        <mesh filename="meshes/mesh164.obj" scale="0.100000 0.100000 0.100000" />
      </geometry>
    </visual>
    <collision>
      <origin xyz="0.000000 0.000000 0.000000" rpy="0. 0. 0." />
      <geometry>
        <mesh filename="meshes/mesh0.obj" scale="0.100000 0.100000 0.100000" />
      </geometry>
    </collision>
    <collision>
      <origin xyz="0.000000 0.000000 0.000000" rpy="0. 0. 0." />
      <geometry>
        <mesh filename="meshes/mesh1.obj" scale="0.100000 0.100000 0.100000" />
      </geometry>
    </collision>
    <collision>
      <origin xyz="0.000000 0.000000 0.000000" rpy="0. 0. 0." />
      <geometry>
        <mesh filename="meshes/mesh2.obj" scale="0.100000 0.100000 0.100000" />
      </geometry>
    </collision>
    <collision>
      <origin xyz="0.000000 0.000000 0.000000" rpy="0. 0. 0." />
      <geometry>
        <mesh filename="meshes/mesh3.obj" scale="0.100000 0.100000 0.100000" />
      </geometry>
    </collision>
    <collision>
      <origin xyz="0.000000 0.000000 0.000000" rpy="0. 0. 0." />
      <geometry>
        <mesh filename="meshes/mesh4.obj" scale="0.100000 0.100000 0.100000" />
      </geometry>
    </collision>
    <collision>
      <origin xyz="0.000000 0.000000 0.000000" rpy="0. 0. 0." />
      <geometry>
        <mesh filename="meshes/mesh5.obj" scale="0.100000 0.100000 0.100000" />
      </geometry>
    </collision>
    <collision>
      <origin xyz="0.000000 0.000000 0.000000" rpy="0. 0. 0." />
      <geometry>
        <mesh filename="meshes/mesh6.obj" scale="0.100000 0.100000 0.100000" />
      </geometry>
    </collision>
    <collision>
      <origin xyz="0.000000 0.000000 0.000000" rpy="0. 0. 0." />
      <geometry>
        <mesh filename="meshes/mesh7.obj" scale="0.100000 0.100000 0.100000" />
      </geometry>
    </collision>
    <collision>
      <origin xyz="0.000000 0.000000 0.000000" rpy="0. 0. 0." />
      <geometry>
        <mesh filename="meshes/mesh8.obj" scale="0.100000 0.100000 0.100000" />
      </geometry>
    </collision>
    <collision>
      <origin xyz="0.000000 0.000000 0.000000" rpy="0. 0. 0." />
      <geometry>
        <mesh filename="meshes/mesh9.obj" scale="0.100000 0.100000 0.100000" />
      </geometry>
    </collision>
    <collision>
      <origin xyz="0.000000 0.000000 0.000000" rpy="0. 0. 0." />
      <geometry>
        <mesh filename="meshes/mesh10.obj" scale="0.100000 0.100000 0.100000" />
      </geometry>
    </collision>
    <collision>
      <origin xyz="0.000000 0.000000 0.000000" rpy="0. 0. 0." />
      <geometry>
        <mesh filename="meshes/mesh11.obj" scale="0.100000 0.100000 0.100000" />
      </geometry>
    </collision>
    <collision>
      <origin xyz="0.000000 0.000000 0.000000" rpy="0. 0. 0." />
      <geometry>
        <mesh filename="meshes/mesh12.obj" scale="0.100000 0.100000 0.100000" />
      </geometry>
    </collision>
    <collision>
      <origin xyz="0.000000 0.000000 0.000000" rpy="0. 0. 0." />
      <geometry>
        <mesh filename="meshes/mesh13.obj" scale="0.100000 0.100000 0.100000" />
      </geometry>
    </collision>
    <collision>
      <origin xyz="0.000000 0.000000 0.000000" rpy="0. 0. 0." />
      <geometry>
        <mesh filename="meshes/mesh14.obj" scale="0.100000 0.100000 0.100000" />
      </geometry>
    </collision>
    <collision>
      <origin xyz="0.000000 0.000000 0.000000" rpy="0. 0. 0." />
      <geometry>
        <mesh filename="meshes/mesh15.obj" scale="0.100000 0.100000 0.100000" />
      </geometry>
    </collision>
    <collision>
      <origin xyz="0.000000 0.000000 0.000000" rpy="0. 0. 0." />
      <geometry>
        <mesh filename="meshes/mesh16.obj" scale="0.100000 0.100000 0.100000" />
      </geometry>
    </collision>
    <collision>
      <origin xyz="0.000000 0.000000 0.000000" rpy="0. 0. 0." />
      <geometry>
        <mesh filename="meshes/mesh17.obj" scale="0.100000 0.100000 0.100000" />
      </geometry>
    </collision>
    <collision>
      <origin xyz="0.000000 0.000000 0.000000" rpy="0. 0. 0." />
      <geometry>
        <mesh filename="meshes/mesh18.obj" scale="0.100000 0.100000 0.100000" />
      </geometry>
    </collision>
    <collision>
      <origin xyz="0.000000 0.000000 0.000000" rpy="0. 0. 0." />
      <geometry>
        <mesh filename="meshes/mesh19.obj" scale="0.100000 0.100000 0.100000" />
      </geometry>
    </collision>
    <collision>
      <origin xyz="0.000000 0.000000 0.000000" rpy="0. 0. 0." />
      <geometry>
        <mesh filename="meshes/mesh20.obj" scale="0.100000 0.100000 0.100000" />
      </geometry>
    </collision>
    <collision>
      <origin xyz="0.000000 0.000000 0.000000" rpy="0. 0. 0." />
      <geometry>
        <mesh filename="meshes/mesh21.obj" scale="0.100000 0.100000 0.100000" />
      </geometry>
    </collision>
    <collision>
      <origin xyz="0.000000 0.000000 0.000000" rpy="0. 0. 0." />
      <geometry>
        <mesh filename="meshes/mesh22.obj" scale="0.100000 0.100000 0.100000" />
      </geometry>
    </collision>
    <collision>
      <origin xyz="0.000000 0.000000 0.000000" rpy="0. 0. 0." />
      <geometry>
        <mesh filename="meshes/mesh23.obj" scale="0.100000 0.100000 0.100000" />
      </geometry>
    </collision>
    <collision>
      <origin xyz="0.000000 0.000000 0.000000" rpy="0. 0. 0." />
      <geometry>
        <mesh filename="meshes/mesh24.obj" scale="0.100000 0.100000 0.100000" />
      </geometry>
    </collision>
    <collision>
      <origin xyz="0.000000 0.000000 0.000000" rpy="0. 0. 0." />
      <geometry>
        <mesh filename="meshes/mesh25.obj" scale="0.100000 0.100000 0.100000" />
      </geometry>
    </collision>
    <collision>
      <origin xyz="0.000000 0.000000 0.000000" rpy="0. 0. 0." />
      <geometry>
        <mesh filename="meshes/mesh26.obj" scale="0.100000 0.100000 0.100000" />
      </geometry>
    </collision>
    <collision>
      <origin xyz="0.000000 0.000000 0.000000" rpy="0. 0. 0." />
      <geometry>
        <mesh filename="meshes/mesh27.obj" scale="0.100000 0.100000 0.100000" />
      </geometry>
    </collision>
    <collision>
      <origin xyz="0.000000 0.000000 0.000000" rpy="0. 0. 0." />
      <geometry>
        <mesh filename="meshes/mesh28.obj" scale="0.100000 0.100000 0.100000" />
      </geometry>
    </collision>
    <collision>
      <origin xyz="0.000000 0.000000 0.000000" rpy="0. 0. 0." />
      <geometry>
        <mesh filename="meshes/mesh29.obj" scale="0.100000 0.100000 0.100000" />
      </geometry>
    </collision>
    <collision>
      <origin xyz="0.000000 0.000000 0.000000" rpy="0. 0. 0." />
      <geometry>
        <mesh filename="meshes/mesh30.obj" scale="0.100000 0.100000 0.100000" />
      </geometry>
    </collision>
    <collision>
      <origin xyz="0.000000 0.000000 0.000000" rpy="0. 0. 0." />
      <geometry>
        <mesh filename="meshes/mesh31.obj" scale="0.100000 0.100000 0.100000" />
      </geometry>
    </collision>
    <collision>
      <origin xyz="0.000000 0.000000 0.000000" rpy="0. 0. 0." />
      <geometry>
        <mesh filename="meshes/mesh32.obj" scale="0.100000 0.100000 0.100000" />
      </geometry>
    </collision>
    <collision>
      <origin xyz="0.000000 0.000000 0.000000" rpy="0. 0. 0." />
      <geometry>
        <mesh filename="meshes/mesh33.obj" scale="0.100000 0.100000 0.100000" />
      </geometry>
    </collision>
    <collision>
      <origin xyz="0.000000 0.000000 0.000000" rpy="0. 0. 0." />
      <geometry>
        <mesh filename="meshes/mesh34.obj" scale="0.100000 0.100000 0.100000" />
      </geometry>
    </collision>
    <collision>
      <origin xyz="0.000000 0.000000 0.000000" rpy="0. 0. 0." />
      <geometry>
        <mesh filename="meshes/mesh35.obj" scale="0.100000 0.100000 0.100000" />
      </geometry>
    </collision>
    <collision>
      <origin xyz="0.000000 0.000000 0.000000" rpy="0. 0. 0." />
      <geometry>
        <mesh filename="meshes/mesh36.obj" scale="0.100000 0.100000 0.100000" />
      </geometry>
    </collision>
    <collision>
      <origin xyz="0.000000 0.000000 0.000000" rpy="0. 0. 0." />
      <geometry>
        <mesh filename="meshes/mesh37.obj" scale="0.100000 0.100000 0.100000" />
      </geometry>
    </collision>
    <collision>
      <origin xyz="0.000000 0.000000 0.000000" rpy="0. 0. 0." />
      <geometry>
        <mesh filename="meshes/mesh38.obj" scale="0.100000 0.100000 0.100000" />
      </geometry>
    </collision>
    <collision>
      <origin xyz="0.000000 0.000000 0.000000" rpy="0. 0. 0." />
      <geometry>
        <mesh filename="meshes/mesh39.obj" scale="0.100000 0.100000 0.100000" />
      </geometry>
    </collision>
    <collision>
      <origin xyz="0.000000 0.000000 0.000000" rpy="0. 0. 0." />
      <geometry>
        <mesh filename="meshes/mesh40.obj" scale="0.100000 0.100000 0.100000" />
      </geometry>
    </collision>
    <collision>
      <origin xyz="0.000000 0.000000 0.000000" rpy="0. 0. 0." />
      <geometry>
        <mesh filename="meshes/mesh41.obj" scale="0.100000 0.100000 0.100000" />
      </geometry>
    </collision>
    <collision>
      <origin xyz="0.000000 0.000000 0.000000" rpy="0. 0. 0." />
      <geometry>
        <mesh filename="meshes/mesh42.obj" scale="0.100000 0.100000 0.100000" />
      </geometry>
    </collision>
    <collision>
      <origin xyz="0.000000 0.000000 0.000000" rpy="0. 0. 0." />
      <geometry>
        <mesh filename="meshes/mesh43.obj" scale="0.100000 0.100000 0.100000" />
      </geometry>
    </collision>
    <collision>
      <origin xyz="0.000000 0.000000 0.000000" rpy="0. 0. 0." />
      <geometry>
        <mesh filename="meshes/mesh44.obj" scale="0.100000 0.100000 0.100000" />
      </geometry>
    </collision>
    <collision>
      <origin xyz="0.000000 0.000000 0.000000" rpy="0. 0. 0." />
      <geometry>
        <mesh filename="meshes/mesh45.obj" scale="0.100000 0.100000 0.100000" />
      </geometry>
    </collision>
    <collision>
      <origin xyz="0.000000 0.000000 0.000000" rpy="0. 0. 0." />
      <geometry>
        <mesh filename="meshes/mesh46.obj" scale="0.100000 0.100000 0.100000" />
      </geometry>
    </collision>
    <collision>
      <origin xyz="0.000000 0.000000 0.000000" rpy="0. 0. 0." />
      <geometry>
        <mesh filename="meshes/mesh47.obj" scale="0.100000 0.100000 0.100000" />
      </geometry>
    </collision>
    <collision>
      <origin xyz="0.000000 0.000000 0.000000" rpy="0. 0. 0." />
      <geometry>
        <mesh filename="meshes/mesh48.obj" scale="0.100000 0.100000 0.100000" />
      </geometry>
    </collision>
    <collision>
      <origin xyz="0.000000 0.000000 0.000000" rpy="0. 0. 0." />
      <geometry>
        <mesh filename="meshes/mesh49.obj" scale="0.100000 0.100000 0.100000" />
      </geometry>
    </collision>
    <collision>
      <origin xyz="0.000000 0.000000 0.000000" rpy="0. 0. 0." />
      <geometry>
        <mesh filename="meshes/mesh50.obj" scale="0.100000 0.100000 0.100000" />
      </geometry>
    </collision>
    <collision>
      <origin xyz="0.000000 0.000000 0.000000" rpy="0. 0. 0." />
      <geometry>
        <mesh filename="meshes/mesh51.obj" scale="0.100000 0.100000 0.100000" />
      </geometry>
    </collision>
    <collision>
      <origin xyz="0.000000 0.000000 0.000000" rpy="0. 0. 0." />
      <geometry>
        <mesh filename="meshes/mesh52.obj" scale="0.100000 0.100000 0.100000" />
      </geometry>
    </collision>
    <collision>
      <origin xyz="0.000000 0.000000 0.000000" rpy="0. 0. 0." />
      <geometry>
        <mesh filename="meshes/mesh53.obj" scale="0.100000 0.100000 0.100000" />
      </geometry>
    </collision>
    <collision>
      <origin xyz="0.000000 0.000000 0.000000" rpy="0. 0. 0." />
      <geometry>
        <mesh filename="meshes/mesh54.obj" scale="0.100000 0.100000 0.100000" />
      </geometry>
    </collision>
    <collision>
      <origin xyz="0.000000 0.000000 0.000000" rpy="0. 0. 0." />
      <geometry>
        <mesh filename="meshes/mesh55.obj" scale="0.100000 0.100000 0.100000" />
      </geometry>
    </collision>
    <collision>
      <origin xyz="0.000000 0.000000 0.000000" rpy="0. 0. 0." />
      <geometry>
        <mesh filename="meshes/mesh56.obj" scale="0.100000 0.100000 0.100000" />
      </geometry>
    </collision>
    <collision>
      <origin xyz="0.000000 0.000000 0.000000" rpy="0. 0. 0." />
      <geometry>
        <mesh filename="meshes/mesh57.obj" scale="0.100000 0.100000 0.100000" />
      </geometry>
    </collision>
    <collision>
      <origin xyz="0.000000 0.000000 0.000000" rpy="0. 0. 0." />
      <geometry>
        <mesh filename="meshes/mesh58.obj" scale="0.100000 0.100000 0.100000" />
      </geometry>
    </collision>
    <collision>
      <origin xyz="0.000000 0.000000 0.000000" rpy="0. 0. 0." />
      <geometry>
        <mesh filename="meshes/mesh59.obj" scale="0.100000 0.100000 0.100000" />
      </geometry>
    </collision>
    <collision>
      <origin xyz="0.000000 0.000000 0.000000" rpy="0. 0. 0." />
      <geometry>
        <mesh filename="meshes/mesh60.obj" scale="0.100000 0.100000 0.100000" />
      </geometry>
    </collision>
    <collision>
      <origin xyz="0.000000 0.000000 0.000000" rpy="0. 0. 0." />
      <geometry>
        <mesh filename="meshes/mesh61.obj" scale="0.100000 0.100000 0.100000" />
      </geometry>
    </collision>
    <collision>
      <origin xyz="0.000000 0.000000 0.000000" rpy="0. 0. 0." />
      <geometry>
        <mesh filename="meshes/mesh62.obj" scale="0.100000 0.100000 0.100000" />
      </geometry>
    </collision>
    <collision>
      <origin xyz="0.000000 0.000000 0.000000" rpy="0. 0. 0." />
      <geometry>
        <mesh filename="meshes/mesh63.obj" scale="0.100000 0.100000 0.100000" />
      </geometry>
    </collision>
    <collision>
      <origin xyz="0.000000 0.000000 0.000000" rpy="0. 0. 0." />
      <geometry>
        <mesh filename="meshes/mesh64.obj" scale="0.100000 0.100000 0.100000" />
      </geometry>
    </collision>
    <collision>
      <origin xyz="0.000000 0.000000 0.000000" rpy="0. 0. 0." />
      <geometry>
        <mesh filename="meshes/mesh65.obj" scale="0.100000 0.100000 0.100000" />
      </geometry>
    </collision>
    <collision>
      <origin xyz="0.000000 0.000000 0.000000" rpy="0. 0. 0." />
      <geometry>
        <mesh filename="meshes/mesh66.obj" scale="0.100000 0.100000 0.100000" />
      </geometry>
    </collision>
    <collision>
      <origin xyz="0.000000 0.000000 0.000000" rpy="0. 0. 0." />
      <geometry>
        <mesh filename="meshes/mesh67.obj" scale="0.100000 0.100000 0.100000" />
      </geometry>
    </collision>
    <collision>
      <origin xyz="0.000000 0.000000 0.000000" rpy="0. 0. 0." />
      <geometry>
        <mesh filename="meshes/mesh68.obj" scale="0.100000 0.100000 0.100000" />
      </geometry>
    </collision>
    <collision>
      <origin xyz="0.000000 0.000000 0.000000" rpy="0. 0. 0." />
      <geometry>
        <mesh filename="meshes/mesh69.obj" scale="0.100000 0.100000 0.100000" />
      </geometry>
    </collision>
    <collision>
      <origin xyz="0.000000 0.000000 0.000000" rpy="0. 0. 0." />
      <geometry>
        <mesh filename="meshes/mesh70.obj" scale="0.100000 0.100000 0.100000" />
      </geometry>
    </collision>
    <collision>
      <origin xyz="0.000000 0.000000 0.000000" rpy="0. 0. 0." />
      <geometry>
        <mesh filename="meshes/mesh71.obj" scale="0.100000 0.100000 0.100000" />
      </geometry>
    </collision>
    <collision>
      <origin xyz="0.000000 0.000000 0.000000" rpy="0. 0. 0." />
      <geometry>
        <mesh filename="meshes/mesh164.obj" scale="0.100000 0.100000 0.100000" />
      </geometry>
    </collision>
  </link>
  <link name="front_left_foot">
    <visual>
      <origin xyz="36.000000 -15.500000 19.370300" rpy="0. 0. 0." />
      <geometry>
        <mesh filename="meshes/mesh114.obj" scale="0.100000 0.100000 0.100000" />
      </geometry>
    </visual>
    <visual>
      <origin xyz="36.000000 -15.500000 19.370300" rpy="0. 0. 0." />
      <geometry>
        <mesh filename="meshes/mesh115.obj" scale="0.100000 0.100000 0.100000" />
      </geometry>
    </visual>
    <visual>
      <origin xyz="36.000000 -15.500000 19.370300" rpy="0. 0. 0." />
      <geometry>
        <mesh filename="meshes/mesh116.obj" scale="0.100000 0.100000 0.100000" />
      </geometry>
    </visual>
    <visual>
      <origin xyz="36.000000 -15.500000 19.370300" rpy="0. 0. 0." />
      <geometry>
        <mesh filename="meshes/mesh117.obj" scale="0.100000 0.100000 0.100000" />
      </geometry>
    </visual>
    <collision>
      <origin xyz="36.000000 -15.500000 19.370300" rpy="0. 0. 0." />
      <geometry>
        <mesh filename="meshes/mesh114.obj" scale="0.100000 0.100000 0.100000" />
      </geometry>
    </collision>
    <collision>
      <origin xyz="36.000000 -15.500000 19.370300" rpy="0. 0. 0." />
      <geometry>
        <mesh filename="meshes/mesh115.obj" scale="0.100000 0.100000 0.100000" />
      </geometry>
    </collision>
    <collision>
      <origin xyz="36.000000 -15.500000 19.370300" rpy="0. 0. 0." />
      <geometry>
        <mesh filename="meshes/mesh116.obj" scale="0.100000 0.100000 0.100000" />
      </geometry>
    </collision>
    <collision>
      <origin xyz="36.000000 -15.500000 19.370300" rpy="0. 0. 0." />
      <geometry>
        <mesh filename="meshes/mesh117.obj" scale="0.100000 0.100000 0.100000" />
      </geometry>
    </collision>
  </link>
  <link name="front_left_lower_leg">
    <visual>
      <origin xyz="36.000000 -25.500000 19.370300" rpy="0. 0. 0." />
      <geometry>
        <mesh filename="meshes/mesh101.obj" scale="0.100000 0.100000 0.100000" />
      </geometry>
    </visual>
    <visual>
      <origin xyz="36.000000 -25.500000 19.370300" rpy="0. 0. 0." />
      <geometry>
        <mesh filename="meshes/mesh102.obj" scale="0.100000 0.100000 0.100000" />
      </geometry>
    </visual>
    <visual>
      <origin xyz="36.000000 -25.500000 19.370300" rpy="0. 0. 0." />
      <geometry>
        <mesh filename="meshes/mesh103.obj" scale="0.100000 0.100000 0.100000" />
      </geometry>
    </visual>
    <visual>
      <origin xyz="36.000000 -25.500000 19.370300" rpy="0. 0. 0." />
      <geometry>
        <mesh filename="meshes/mesh104.obj" scale="0.100000 0.100000 0.100000" />
      </geometry>
    </visual>
    <visual>
      <origin xyz="36.000000 -25.500000 19.370300" rpy="0. 0. 0." />
      <geometry>
        <mesh filename="meshes/mesh105.obj" scale="0.100000 0.100000 0.100000" />
      </geometry>
    </visual>
    <visual>
      <origin xyz="36.000000 -25.500000 19.370300" rpy="0. 0. 0." />
      <geometry>
        <mesh filename="meshes/mesh106.obj" scale="0.100000 0.100000 0.100000" />
      </geometry>
    </visual>
    <visual>
      <origin xyz="36.000000 -25.500000 19.370300" rpy="0. 0. 0." />
      <geometry>
        <mesh filename="meshes/mesh107.obj" scale="0.100000 0.100000 0.100000" />
      </geometry>
    </visual>
    <visual>
      <origin xyz="36.000000 -25.500000 19.370300" rpy="0. 0. 0." />
      <geometry>
        <mesh filename="meshes/mesh108.obj" scale="0.100000 0.100000 0.100000" />
      </geometry>
    </visual>
    <visual>
      <origin xyz="36.000000 -25.500000 19.370300" rpy="0. 0. 0." />
      <geometry>
        <mesh filename="meshes/mesh109.obj" scale="0.100000 0.100000 0.100000" />
      </geometry>
    </visual>
    <visual>
      <origin xyz="36.000000 -25.500000 19.370300" rpy="0. 0. 0." />
      <geometry>
        <mesh filename="meshes/mesh110.obj" scale="0.100000 0.100000 0.100000" />
      </geometry>
    </visual>
    <visual>
      <origin xyz="36.000000 -25.500000 19.370300" rpy="0. 0. 0." />
      <geometry>
        <mesh filename="meshes/mesh111.obj" scale="0.100000 0.100000 0.100000" />
      </geometry>
    </visual>
    <visual>
      <origin xyz="36.000000 -25.500000 19.370300" rpy="0. 0. 0." />
      <geometry>
        <mesh filename="meshes/mesh112.obj" scale="0.100000 0.100000 0.100000" />
      </geometry>
    </visual>
    <visual>
      <origin xyz="36.000000 -25.500000 19.370300" rpy="0. 0. 0." />
      <geometry>
        <mesh filename="meshes/mesh113.obj" scale="0.100000 0.100000 0.100000" />
      </geometry>
    </visual>
    <collision>
      <origin xyz="36.000000 -25.500000 19.370300" rpy="0. 0. 0." />
      <geometry>
        <mesh filename="meshes/mesh101.obj" scale="0.100000 0.100000 0.100000" />
      </geometry>
    </collision>
    <collision>
      <origin xyz="36.000000 -25.500000 19.370300" rpy="0. 0. 0." />
      <geometry>
        <mesh filename="meshes/mesh102.obj" scale="0.100000 0.100000 0.100000" />
      </geometry>
    </collision>
    <collision>
      <origin xyz="36.000000 -25.500000 19.370300" rpy="0. 0. 0." />
      <geometry>
        <mesh filename="meshes/mesh103.obj" scale="0.100000 0.100000 0.100000" />
      </geometry>
    </collision>
    <collision>
      <origin xyz="36.000000 -25.500000 19.370300" rpy="0. 0. 0." />
      <geometry>
        <mesh filename="meshes/mesh104.obj" scale="0.100000 0.100000 0.100000" />
      </geometry>
    </collision>
    <collision>
      <origin xyz="36.000000 -25.500000 19.370300" rpy="0. 0. 0." />
      <geometry>
        <mesh filename="meshes/mesh105.obj" scale="0.100000 0.100000 0.100000" />
      </geometry>
    </collision>
    <collision>
      <origin xyz="36.000000 -25.500000 19.370300" rpy="0. 0. 0." />
      <geometry>
        <mesh filename="meshes/mesh106.obj" scale="0.100000 0.100000 0.100000" />
      </geometry>
    </collision>
    <collision>
      <origin xyz="36.000000 -25.500000 19.370300" rpy="0. 0. 0." />
      <geometry>
        <mesh filename="meshes/mesh107.obj" scale="0.100000 0.100000 0.100000" />
      </geometry>
    </collision>
    <collision>
      <origin xyz="36.000000 -25.500000 19.370300" rpy="0. 0. 0." />
      <geometry>
        <mesh filename="meshes/mesh108.obj" scale="0.100000 0.100000 0.100000" />
      </geometry>
    </collision>
    <collision>
      <origin xyz="36.000000 -25.500000 19.370300" rpy="0. 0. 0." />
      <geometry>
        <mesh filename="meshes/mesh109.obj" scale="0.100000 0.100000 0.100000" />
      </geometry>
    </collision>
    <collision>
      <origin xyz="36.000000 -25.500000 19.370300" rpy="0. 0. 0." />
      <geometry>
        <mesh filename="meshes/mesh110.obj" scale="0.100000 0.100000 0.100000" />
      </geometry>
    </collision>
    <collision>
      <origin xyz="36.000000 -25.500000 19.370300" rpy="0. 0. 0." />
      <geometry>
        <mesh filename="meshes/mesh111.obj" scale="0.100000 0.100000 0.100000" />
      </geometry>
    </collision>
    <collision>
      <origin xyz="36.000000 -25.500000 19.370300" rpy="0. 0. 0." />
      <geometry>
        <mesh filename="meshes/mesh112.obj" scale="0.100000 0.100000 0.100000" />
      </geometry>
    </collision>
    <collision>
      <origin xyz="36.000000 -25.500000 19.370300" rpy="0. 0. 0." />
      <geometry>
        <mesh filename="meshes/mesh113.obj" scale="0.100000 0.100000 0.100000" />
      </geometry>
    </collision>
  </link>
  <link name="front_left_upper_leg">
    <visual>
      <origin xyz="31.015000 -24.810300 19.280000" rpy="0. 0. 0." />
      <geometry>
        <mesh filename="meshes/mesh95.obj" scale="0.100000 0.100000 0.100000" />
      </geometry>
    </visual>
    <visual>
      <origin xyz="31.015000 -24.810300 19.280000" rpy="0. 0. 0." />
      <geometry>
        <mesh filename="meshes/mesh96.obj" scale="0.100000 0.100000 0.100000" />
      </geometry>
    </visual>
    <visual>
      <origin xyz="31.015000 -24.810300 19.280000" rpy="0. 0. 0." />
      <geometry>
        <mesh filename="meshes/mesh97.obj" scale="0.100000 0.100000 0.100000" />
      </geometry>
    </visual>
    <visual>
      <origin xyz="31.015000 -24.810300 19.280000" rpy="0. 0. 0." />
      <geometry>
        <mesh filename="meshes/mesh98.obj" scale="0.100000 0.100000 0.100000" />
      </geometry>
    </visual>
    <visual>
      <origin xyz="31.015000 -24.810300 19.280000" rpy="0. 0. 0." />
      <geometry>
        <mesh filename="meshes/mesh99.obj" scale="0.100000 0.100000 0.100000" />
      </geometry>
    </visual>
    <visual>
      <origin xyz="31.015000 -24.810300 19.280000" rpy="0. 0. 0." />
      <geometry>
        <mesh filename="meshes/mesh100.obj" scale="0.100000 0.100000 0.100000" />
      </geometry>
    </visual>
    <collision>
      <origin xyz="31.015000 -24.810300 19.280000" rpy="0. 0. 0." />
      <geometry>
        <mesh filename="meshes/mesh95.obj" scale="0.100000 0.100000 0.100000" />
      </geometry>
    </collision>
    <collision>
      <origin xyz="31.015000 -24.810300 19.280000" rpy="0. 0. 0." />
      <geometry>
        <mesh filename="meshes/mesh96.obj" scale="0.100000 0.100000 0.100000" />
      </geometry>
    </collision>
    <collision>
      <origin xyz="31.015000 -24.810300 19.280000" rpy="0. 0. 0." />
      <geometry>
        <mesh filename="meshes/mesh97.obj" scale="0.100000 0.100000 0.100000" />
      </geometry>
    </collision>
    <collision>
      <origin xyz="31.015000 -24.810300 19.280000" rpy="0. 0. 0." />
      <geometry>
        <mesh filename="meshes/mesh98.obj" scale="0.100000 0.100000 0.100000" />
      </geometry>
    </collision>
    <collision>
      <origin xyz="31.015000 -24.810300 19.280000" rpy="0. 0. 0." />
      <geometry>
        <mesh filename="meshes/mesh99.obj" scale="0.100000 0.100000 0.100000" />
      </geometry>
    </collision>
    <collision>
      <origin xyz="31.015000 -24.810300 19.280000" rpy="0. 0. 0." />
      <geometry>
        <mesh filename="meshes/mesh100.obj" scale="0.100000 0.100000 0.100000" />
      </geometry>
    </collision>
  </link>
  <link name="front_right_foot">
    <visual>
      <origin xyz="2.500000 -15.500000 19.370300" rpy="0. 0. 0." />
      <geometry>
        <mesh filename="meshes/mesh91.obj" scale="0.100000 0.100000 0.100000" />
      </geometry>
    </visual>
    <visual>
      <origin xyz="2.500000 -15.500000 19.370300" rpy="0. 0. 0." />
      <geometry>
        <mesh filename="meshes/mesh92.obj" scale="0.100000 0.100000 0.100000" />
      </geometry>
    </visual>
    <visual>
      <origin xyz="2.500000 -15.500000 19.370300" rpy="0. 0. 0." />
      <geometry>
        <mesh filename="meshes/mesh93.obj" scale="0.100000 0.100000 0.100000" />
      </geometry>
    </visual>
    <visual>
      <origin xyz="2.500000 -15.500000 19.370300" rpy="0. 0. 0." />
      <geometry>
        <mesh filename="meshes/mesh94.obj" scale="0.100000 0.100000 0.100000" />
      </geometry>
    </visual>
    <collision>
      <origin xyz="2.500000 -15.500000 19.370300" rpy="0. 0. 0." />
      <geometry>
        <mesh filename="meshes/mesh91.obj" scale="0.100000 0.100000 0.100000" />
      </geometry>
    </collision>
    <collision>
      <origin xyz="2.500000 -15.500000 19.370300" rpy="0. 0. 0." />
      <geometry>
        <mesh filename="meshes/mesh92.obj" scale="0.100000 0.100000 0.100000" />
      </geometry>
    </collision>
    <collision>
      <origin xyz="2.500000 -15.500000 19.370300" rpy="0. 0. 0." />
      <geometry>
        <mesh filename="meshes/mesh93.obj" scale="0.100000 0.100000 0.100000" />
      </geometry>
    </collision>
    <collision>
      <origin xyz="2.500000 -15.500000 19.370300" rpy="0. 0. 0." />
      <geometry>
        <mesh filename="meshes/mesh94.obj" scale="0.100000 0.100000 0.100000" />
      </geometry>
    </collision>
  </link>
  <link name="front_right_lower_leg">
    <visual>
      <origin xyz="2.500000 -25.500000 19.370300" rpy="0. 0. 0." />
      <geometry>
        <mesh filename="meshes/mesh78.obj" scale="0.100000 0.100000 0.100000" />
      </geometry>
    </visual>
    <visual>
      <origin xyz="2.500000 -25.500000 19.370300" rpy="0. 0. 0." />
      <geometry>
        <mesh filename="meshes/mesh79.obj" scale="0.100000 0.100000 0.100000" />
      </geometry>
    </visual>
    <visual>
      <origin xyz="2.500000 -25.500000 19.370300" rpy="0. 0. 0." />
      <geometry>
        <mesh filename="meshes/mesh80.obj" scale="0.100000 0.100000 0.100000" />
      </geometry>
    </visual>
    <visual>
      <origin xyz="2.500000 -25.500000 19.370300" rpy="0. 0. 0." />
      <geometry>
        <mesh filename="meshes/mesh81.obj" scale="0.100000 0.100000 0.100000" />
      </geometry>
    </visual>
    <visual>
      <origin xyz="2.500000 -25.500000 19.370300" rpy="0. 0. 0." />
      <geometry>
        <mesh filename="meshes/mesh82.obj" scale="0.100000 0.100000 0.100000" />
      </geometry>
    </visual>
    <visual>
      <origin xyz="2.500000 -25.500000 19.370300" rpy="0. 0. 0." />
      <geometry>
        <mesh filename="meshes/mesh83.obj" scale="0.100000 0.100000 0.100000" />
      </geometry>
    </visual>
    <visual>
      <origin xyz="2.500000 -25.500000 19.370300" rpy="0. 0. 0." />
      <geometry>
        <mesh filename="meshes/mesh84.obj" scale="0.100000 0.100000 0.100000" />
      </geometry>
    </visual>
    <visual>
      <origin xyz="2.500000 -25.500000 19.370300" rpy="0. 0. 0." />
      <geometry>
        <mesh filename="meshes/mesh85.obj" scale="0.100000 0.100000 0.100000" />
      </geometry>
    </visual>
    <visual>
      <origin xyz="2.500000 -25.500000 19.370300" rpy="0. 0. 0." />
      <geometry>
        <mesh filename="meshes/meshes/mesh86.obj" scale="0.100000 0.100000 0.100000" />
      </geometry>
    </visual>
    <visual>
      <origin xyz="2.500000 -25.500000 19.370300" rpy="0. 0. 0." />
      <geometry>
        <mesh filename="meshes/mesh87.obj" scale="0.100000 0.100000 0.100000" />
      </geometry>
    </visual>
    <visual>
      <origin xyz="2.500000 -25.500000 19.370300" rpy="0. 0. 0." />
      <geometry>
        <mesh filename="meshes/mesh88.obj" scale="0.100000 0.100000 0.100000" />
      </geometry>
    </visual>
    <visual>
      <origin xyz="2.500000 -25.500000 19.370300" rpy="0. 0. 0." />
      <geometry>
        <mesh filename="meshes/mesh89.obj" scale="0.100000 0.100000 0.100000" />
      </geometry>
    </visual>
    <visual>
      <origin xyz="2.500000 -25.500000 19.370300" rpy="0. 0. 0." />
      <geometry>
        <mesh filename="meshes/mesh90.obj" scale="0.100000 0.100000 0.100000" />
      </geometry>
    </visual>
    <!-- Additional collision elements omitted for brevity -->
  </link>
  <!-- Additional links with proper mesh paths -->
</robot>