<?xml version='1.0' encoding='utf-8'?>
<robot name="quad2">
  
  <!-- Add world link and corrective rotation -->
  <link name="world"/>
  
  <joint name="world_to_base_corrective" type="fixed">
    <parent link="world"/>
    <child link="base_link"/>
    <origin xyz="0 0 0" rpy="1.5708 0 0"/>
  </joint>

  <joint name="front_left_ankle" type="revolute">
    <origin xyz="0.000000 -10.000000 0.000000" rpy="0. 0. 0." />
    <parent link="front_left_lower_leg" />
    <child link="front_left_foot" />
    <axis xyz="0. 0. 1." />
    <limit lower="0." upper="3.1415927" effort="0." velocity="0." />
  </joint>
  <joint name="front_left_hip" type="revolute">
    <origin xyz="-31.015000 24.810300 -19.280000" rpy="0. 0. 0." />
    <parent link="base_link" />
    <child link="front_left_upper_leg" />
    <axis xyz="0. 1. 0." />
    <limit lower="-1.5707963" upper="1.5707963" effort="0." velocity="0." />
  </joint>
  <joint name="front_left_knee" type="revolute">
    <origin xyz="-4.985001 0.689700 -0.090300" rpy="0. 0. 0." />
    <parent link="front_left_upper_leg" />
    <child link="front_left_lower_leg" />
    <axis xyz="0. 0. 1." />
    <limit lower="-3.1415927" upper="0." effort="0." velocity="0." />
  </joint>
  <joint name="front_right_ankle" type="revolute">
    <origin xyz="0.000000 -10.000000 0.000000" rpy="0. 0. 0." />
    <parent link="front_right_lower_leg" />
    <child link="front_right_foot" />
    <axis xyz="0. 0. 1." />
    <limit lower="-3.1415927" upper="0." effort="0." velocity="0." />
  </joint>
  <joint name="front_right_hip" type="revolute">
    <origin xyz="-7.485000 24.810300 -19.280000" rpy="0. 0. 0." />
    <parent link="base_link" />
    <child link="front_right_upper_leg" />
    <axis xyz="0. 1. 0." />
    <limit lower="-1.5707963" upper="1.5707963" effort="0." velocity="0." />
  </joint>
  <joint name="front_right_knee" type="revolute">
    <origin xyz="4.985000 0.689700 -0.090300" rpy="0. 0. 0." />
    <parent link="front_right_upper_leg" />
    <child link="front_right_lower_leg" />
    <axis xyz="0. 0. 1." />
    <limit lower="0." upper="3.1415927" effort="0." velocity="0." />
  </joint>
  <joint name="rear_left_ankle" type="revolute">
    <origin xyz="0.000000 -10.000000 0.000000" rpy="0. 0. 0." />
    <parent link="rear_left_lower_leg" />
    <child link="rear_left_foot" />
    <axis xyz="0. 0. 1." />
    <limit lower="0." upper="3.1415927" effort="0." velocity="0." />
  </joint>
  <joint name="rear_left_hip" type="revolute">
    <origin xyz="-31.015000 24.810300 -4.280000" rpy="0. 0. 0." />
    <parent link="base_link" />
    <child link="rear_left_upper_leg" />
    <axis xyz="0. 1. 0." />
    <limit lower="-1.5707963" upper="1.5707963" effort="0." velocity="0." />
  </joint>
  <joint name="rear_left_knee" type="revolute">
    <origin xyz="-4.985001 0.689700 0.090300" rpy="0. 0. 0." />
    <parent link="rear_left_upper_leg" />
    <child link="rear_left_lower_leg" />
    <axis xyz="0. 0. 1." />
    <limit lower="-3.1415927" upper="0." effort="0." velocity="0." />
  </joint>
  <joint name="rear_right_ankle" type="revolute">
    <origin xyz="0.000000 -10.000000 0.000000" rpy="0. 0. 0." />
    <parent link="rear_right_lower_leg" />
    <child link="rear_right_foot" />
    <axis xyz="0. 0. 1." />
    <limit lower="-3.1415927" upper="0." effort="0." velocity="0." />
  </joint>
  <joint name="rear_right_hip" type="revolute">
    <origin xyz="-7.485000 24.810300 -4.280000" rpy="0. 0. 0." />
    <parent link="base_link" />
    <child link="rear_right_upper_leg" />
    <axis xyz="0. 1. 0." />
    <limit lower="-1.5707963" upper="1.5707963" effort="0." velocity="0." />
  </joint>
  <joint name="rear_right_knee" type="revolute">
    <origin xyz="4.985000 0.689700 0.090300" rpy="0. 0. 0." />
    <parent link="rear_right_upper_leg" />
    <child link="rear_right_lower_leg" />
    <axis xyz="0. 0. 1." />
    <limit lower="0." upper="3.1415927" effort="0." velocity="0." />
  </joint>
  <link name="base_link">
    <visual>
      <origin xyz="0.000000 0.000000 0.000000" rpy="0. 0. 0." />
      <geometry>
        <mesh filename="package://quad_description/urdf/meshes/mesh0.obj" scale="0.100000 0.100000 0.100000" />
      </geometry>
    </visual>
    <!-- Additional visual elements for mesh1.obj through mesh164.obj -->
    <!-- (truncated for brevity - full file has 165 mesh components) -->
  </link>
  <!-- Additional links: front_left_foot, front_left_lower_leg, etc. -->
</robot>